Traceback (most recent call last):
  File "/usr/local/lib/python3.4/site-packages/urllib3/connection.py", line 141, in _new_conn
    (self.host, self.port), self.timeout, **extra_kw)
  File "/usr/local/lib/python3.4/site-packages/urllib3/util/connection.py", line 83, in create_connection
    raise err
  File "/usr/local/lib/python3.4/site-packages/urllib3/util/connection.py", line 73, in create_connection
    sock.connect(sa)
ConnectionRefusedError: [Errno 111] Connection refused

During handling of the above exception, another exception occurred:

Traceback (most recent call last):
  File "/usr/local/lib/python3.4/site-packages/urllib3/connectionpool.py", line 601, in urlopen
    chunked=chunked)
  File "/usr/local/lib/python3.4/site-packages/urllib3/connectionpool.py", line 357, in _make_request
    conn.request(method, url, **httplib_request_kw)
  File "/usr/local/lib/python3.4/http/client.py", line 1137, in request
    self._send_request(method, url, body, headers)
  File "/usr/local/lib/python3.4/http/client.py", line 1182, in _send_request
    self.endheaders(body)
  File "/usr/local/lib/python3.4/http/client.py", line 1133, in endheaders
    self._send_output(message_body)
  File "/usr/local/lib/python3.4/http/client.py", line 963, in _send_output
    self.send(msg)
  File "/usr/local/lib/python3.4/http/client.py", line 898, in send
    self.connect()
  File "/usr/local/lib/python3.4/site-packages/urllib3/connection.py", line 166, in connect
    conn = self._new_conn()
  File "/usr/local/lib/python3.4/site-packages/urllib3/connection.py", line 150, in _new_conn
    self, "Failed to establish a new connection: %s" % e)
urllib3.exceptions.NewConnectionError: <urllib3.connection.HTTPConnection object at 0x7f910badd9b0>: Failed to establish a new connection: [Errno 111] Connection refused

During handling of the above exception, another exception occurred:

Traceback (most recent call last):
  File "/usr/local/lib/python3.4/site-packages/requests/adapters.py", line 440, in send
    timeout=timeout
  File "/usr/local/lib/python3.4/site-packages/urllib3/connectionpool.py", line 639, in urlopen
    _stacktrace=sys.exc_info()[2])
  File "/usr/local/lib/python3.4/site-packages/urllib3/util/retry.py", line 388, in increment
    raise MaxRetryError(_pool, url, error or ResponseError(cause))
urllib3.exceptions.MaxRetryError: HTTPConnectionPool(host='10.0.2.15', port=5678): Max retries exceeded with url: /v1.35/containers/json?size=0&limit=-1&trunc_cmd=0&all=0 (Caused by NewConnectionError('<urllib3.connection.HTTPConnection object at 0x7f910badd9b0>: Failed to establish a new connection: [Errno 111] Connection refused',))

During handling of the above exception, another exception occurred:

Traceback (most recent call last):
  File "test.py", line 92, in <module>
    get_container_data()
  File "test.py", line 64, in get_container_data
    container_list.extend(client.containers.list())
  File "/usr/local/lib/python3.4/site-packages/docker/models/containers.py", line 895, in list
    since=since)
  File "/usr/local/lib/python3.4/site-packages/docker/api/container.py", line 204, in containers
    res = self._result(self._get(u, params=params), True)
  File "/usr/local/lib/python3.4/site-packages/docker/utils/decorators.py", line 46, in inner
    return f(self, *args, **kwargs)
  File "/usr/local/lib/python3.4/site-packages/docker/api/client.py", line 194, in _get
    return self.get(url, **self._set_request_timeout(kwargs))
  File "/usr/local/lib/python3.4/site-packages/requests/sessions.py", line 521, in get
    return self.request('GET', url, **kwargs)
  File "/usr/local/lib/python3.4/site-packages/requests/sessions.py", line 508, in request
    resp = self.send(prep, **send_kwargs)
  File "/usr/local/lib/python3.4/site-packages/requests/sessions.py", line 618, in send
    r = adapter.send(request, **kwargs)
  File "/usr/local/lib/python3.4/site-packages/requests/adapters.py", line 508, in send
    raise ConnectionError(e, request=request)
requests.exceptions.ConnectionError: HTTPConnectionPool(host='10.0.2.15', port=5678): Max retries exceeded with url: /v1.35/containers/json?size=0&limit=-1&trunc_cmd=0&all=0 (Caused by NewConnectionError('<urllib3.connection.HTTPConnection object at 0x7f910badd9b0>: Failed to establish a new connection: [Errno 111] Connection refused',))
